Workbook

Sheet Guide
I25: شهادة راتب لحالها | J25: الكوثر
I26: كفيل درجة اولى

Sheet المخزون
A1: TYPE/Name | B1: VIN | C1: Color | D1: KM | E1: Cost | F1: Model | G1: التخمين
G2: المتخصصة | H2: الكوثر | I2: بندار | J2: تمكين | K2: السماحة
A3: BYD Dolphyn | B3: LC0CE4CC9N0160869 | C3: Grey | E3: 12800 | F3: 2022 | G3: 14000 | H3: 13500 | I3: 14300 | J3: 13500 | K3: 14800
A4: Hyundai Enciano | B4: LBE3SBXCXKW000295 | C4: White | E4: 15500 | F4: 2019 | G4: Cash Only | H4: Cash Only | I4: Cash Only | J4: Cash Only | K4: Cash Only
A5: Neta V | B5: LUZAGAGA2NA157536 | C5: Grey | E5: 9700 | F5: 2022 | G5: 11500 | H5: 11000 | K5: 12000
A6: Neta V | C6: White | E6: 8700 | F6: 2021 | G6: 9500 | H6: 9000 | I6: 9000 | K6: 10000
A7: Neta U / FULL | B7: LUZBGAFB8NA166353 | C7: White | E7: 15000 | F7: 2022 | G7: 16000 | H7: 15500 | I7: 16000 | K7: 17000
A8: Neta Aya | C8: White | E8: 10100 | F8: 2023 | G8: 12000 | H8: 11500 | I8: 12000 | K8: 12200
A9: Neta X | B9: LUZBGBFA9PA139033 | C9: Grey | E9: 15500 | F9: 2023 | G9: 17000 | H9: 16500 | I9: 17300 | K9: 18000
A10: BYD Yuan Plus | B10: LGXCE4CB7P2146917 | C10: Grey | E10: 17800 | F10: 2023 | G10: 19000 | H10: 19000 | I10: 19000 | J10: 19000 | K10: 20000
A11: Nammi Box Dong Feng | B11: LDP43A961P9011353 | C11: Cream | E11: 12000 | F11: 2023 | G11: Cash Only | H11: Cash Only | I11: Cash Only | J11: Cash Only | K11: Cash Only
A12: E Golf | B12: LFVNB9AU9L5660365 | C12: White | E12: 12300 | F12: 2021 | G12: 13500 | H12: 13000 | I12: 13000 | J12: 13000 | K12: 13500
A13: LaVida | B13: LSVAX60E8K2018412 | C13: White | E13: 10700 | F13: 2019 | G13: 12000 | H13: 11700 | I13: 11700 | J13: 11700 | K13: 12000
A14: LaVida | B14: LSVAX60E4M2011248 | C14: White | E14: 11500 | F14: 2021 | G14: 13500 | H14: 13000 | I14: 13000 | J14: 13000 | K14: 14000
A15: Nano | B15: LDP42A965N9030472 | C15: White | D15: ZERO | E15: 8250 | F15: 2022 | G15: 9500 | H15: 9000 | I15: 9000 | J15: 9000 | K15: 11000
A16: Honda NS1 | B16: DLVHRS1851P520395 | C16: blue | D16: ZERO | E16: 16700 | F16: 2023 | G16: 18500 | H16: 17500 | I16: 18000 | J16: 17500 | K16: 19000
A17: BYD seagall | B17: LGXCE4CC0R0859119 | C17: Cream | D17: ZERO | E17: 13250 | F17: 2024 | G17: 14500 | H17: 14500 | I17: 14500 | J17: 14500 | K17: 15000
A18: toyota BZ3 | B18: DLFMAT14U8P000370 | C18: basali | E18: 18000 | F18: 2023 | G18: 20500 | H18: 20000 | I18: 20000 | J18: 20000 | K18: 20500
A19: KIA EV5 | B19: LJD2BA1F9P0001202 | C19: SKY BLUE | D19: ZERO | E19: 22000 | F19: 2023 | G19: 25000 | H19: 24000 | I19: 25000 | J19: 24000 | K19: 25000
A20: QUIN BYD EV | B20: LGXCB6DB1P0909066 | C20: YELLOW | D20: ZERO | E20: 13000 | F20: 2023 | G20: 15000 | H20: 14500 | I20: 14500 | J20: 14500 | K20: 15000
A21: BYD E2 20 305 | B21: LC0CB4DBXL0029601 | C21: White | E21: 11300 | F21: 2020 | G21: 12500 | H21: 12000 | I21: 12000 | J21: 12000 | K21: 13000
A22: BYD QIN + EV | B22: LGXCE6DBXL0061585 | C22: White | E22: 10350 | F22: 2020 | G22: 12500 | H22: 12500 | I22: 12500 | J22: 12500 | K22: 12500
A23: HONGQUI EMQ5 | B23: LFPHC7CESN2A11469 | C23: Black | E23: 14250 | F23: 2022 | G23: 16500 | H23: 16000 | I23: 16000 | J23: 16000 | K23: 16500
A24: LEAP T03 | B24: LFZ71AJ50RD091151 | C24: WHITE | D24: ZERO | E24: 9500 | F24: 2024 | G24: 11500 | H24: 11000 | I24: 11000 | J24: 11000 | K24: 11500
A25: FORTHING S60 | B25: LMXF17BE3PZ375017 | C25: WHITE | D25: ZERO | E25: 13200 | F25: 2023 | G25: 15000 | H25: 14500 | I25: 15000 | J25: 14500 | K25: 15000
A26: NANO | B26: LDP42A962N9034415 | C26: Black | D26: ZERO | E26: 8700 | F26: 2022 | G26: 11000 | H26: 10000 | I26: 10500 | J26: 0 | K26: 11000
A27: LEAP T03 | C27: Peach | E27: 7700 | F27: 2022
A28: Nissan Sylphi | B28: LGBH1YEA1KY617517 | C28: WHITE | E28: 8700 | F28: 2019 | G28: 12000 | H28: 12000 | I28: 12000 | J28: 12000 | K28: 13000
A29: Dong Feng Mage | B29: LDP35B96XTG525185 | C29: Black | D29: ZERO | F29: 2026
A30: BYD SONG plus | B30: LGXC74CAXR0909135 | C30: White | D30: ZERO | E30: 24250 | F30: 2024
A31: Toyota BZ4 | B31: LFMJR14T1N0003580 | C31: Black | E31: 22000 | F31: 2022
A32: Changan Eado | B32: 0 | C32: Black | D32: ZERO | E32: 17500 | F32: 2026 | G32: Cash Only | H32: 19500 | I32: Cash Only | J32: Cash Only | K32: Cash Only | L32: 2600
A33: Changan Eado | B33: 0 | C33: Black | D33: ZERO | E33: 16500 | F33: 2026 | G33: Cash Only | H33: 18500 | I33: Cash Only | J33: Cash Only | K33: Cash Only | L33: 2600
A34: Changan Eado | B34: 0 | C34: White | D34: ZERO | E34: 14500 | F34: 2023 | G34: Cash Only | H34: 16500 | I34: Cash Only | J34: Cash Only | K34: Cash Only | L34: 2000
A35: Changan Eado | B35: 0 | C35: White | D35: ZERO | E35: 13000 | F35: 2022 | G35: Cash Only | H35: 15000 | I35: Cash Only | J35: Cash Only | K35: Cash Only
A36: Song pro | B36: LC0C74C44S5130261 | C36: Light Grey | D36: ZERO | E36: 22000 | F36: 2025
A37: BYD QUIN L | B37: LC0C76CA9R4807882 | C37: White | D37: ZERO | F37: 2025
M58: LBE3SBXCXKW000295
M59: Hyundai

Sheet المتخصصة للتمويل
A1: المتخصصة للتمويل | M1: Zero 90 | N1: الاوراق المطلوبة والاعتمادات
A2: TYPE/Name | B2: COLOR | C2: Status | D2: Model | E2: Target Margin | F2: Cost | G2: Price | H2: التخمين | I2: Rate | J2: المبلغ الممول | K2: المصاريف | L2: الدفعة المطلوبة | N2: تعتمد سيارات مؤسسة الرشاد / بدون كفيل 80% / تنازل و رهن
A4: =المخزون!A3 -> BYD Dolphyn | B4: =المخزون!C3 -> Grey | C4: =المخزون!D3 -> 0 | D4: =المخزون!F3 -> 2022 | E4: 1000 | F4: =المخزون!E3 -> 12800 | G4: =E4+F4 -> 13800 | H4: =المخزون!G3 -> 14000 | I4: 0.85 | J4: =H4*I4 -> 11900 | K4: 1200 | L4: =(G4+K4)-J4 -> 3100 | N4: هوية/كفيل انثى
A5: =المخزون!A4 -> Hyundai Enciano | B5: =المخزون!C4 -> White | C5: =المخزون!D4 -> 0 | D5: =المخزون!F4 -> 2019 | E5: 1000 | F5: =المخزون!E4 -> 15500 | G5: =E5+F5 -> 16500 | H5: =المخزون!G4 -> Cash Only | I5: 0.85 | J5: =H5*I5 -> #VALUE! | K5: 1200 | L5: =(G5+K5)-J5 -> #VALUE! | N5: فاتورة كهرباء
A6: =المخزون!A5 -> Neta V | B6: =المخزون!C5 -> Grey | C6: =المخزون!D5 -> 0 | D6: =المخزون!F5 -> 2022 | E6: 1000 | F6: =المخزون!E5 -> 9700 | G6: =E6+F6 -> 10700 | H6: =المخزون!G5 -> 11500 | I6: 0.85 | J6: =H6*I6 -> 9775 | K6: 1200 | L6: =(G6+K6)-J6 -> 2125 | N6: دفتر عائلة
A7: =المخزون!A6 -> Neta V | B7: =المخزون!C6 -> White | C7: =المخزون!D6 -> 0 | D7: =المخزون!F6 -> 2021 | E7: 1000 | F7: =المخزون!E6 -> 8700 | G7: =E7+F7 -> 9700 | H7: =المخزون!G6 -> 9500 | I7: 0.85 | J7: =H7*I7 -> 8075 | K7: 1200 | L7: =(G7+K7)-J7 -> 2825 | N7: عقد ايجار
A8: =المخزون!A7 -> Neta U / FULL | B8: =المخزون!C7 -> White | C8: =المخزون!D7 -> 0 | D8: =المخزون!F7 -> 2022 | E8: 1000 | F8: =المخزون!E7 -> 15000 | G8: =E8+F8 -> 16000 | H8: =المخزون!G7 -> 16000 | I8: 0.85 | J8: =H8*I8 -> 13600 | K8: 1200 | L8: =(G8+K8)-J8 -> 3600 | N8: المستعمل عمر 7 سنوات او اقل
A9: =المخزون!A8 -> Neta Aya | B9: =المخزون!C8 -> White | C9: =المخزون!D8 -> 0 | D9: =المخزون!F8 -> 2023 | E9: 1000 | F9: =المخزون!E8 -> 10100 | G9: =E9+F9 -> 11100 | H9: =المخزون!G8 -> 12000 | I9: 0.85 | J9: =H9*I9 -> 10200 | K9: 1200 | L9: =(G9+K9)-J9 -> 2100
A10: =المخزون!A9 -> Neta X | B10: =المخزون!C9 -> Grey | C10: =المخزون!D9 -> 0 | D10: =المخزون!F9 -> 2023 | E10: 1000 | F10: =المخزون!E9 -> 15500 | G10: =E10+F10 -> 16500 | H10: =المخزون!G9 -> 17000 | I10: 0.85 | J10: =H10*I10 -> 14450 | K10: 1200 | L10: =(G10+K10)-J10 -> 3250
A11: =المخزون!A10 -> BYD Yuan Plus | B11: =المخزون!C10 -> Grey | C11: =المخزون!D10 -> 0 | D11: =المخزون!F10 -> 2023 | E11: 1000 | F11: =المخزون!E10 -> 17800 | G11: =E11+F11 -> 18800 | H11: =المخزون!G10 -> 19000 | I11: 0.85 | J11: =H11*I11 -> 16150 | K11: 1200 | L11: =(G11+K11)-J11 -> 3850
A12: =المخزون!A11 -> Nammi Box Dong Feng | B12: =المخزون!C11 -> Cream | C12: =المخزون!D11 -> 0 | D12: =المخزون!F11 -> 2023 | E12: 1000 | F12: =المخزون!E11 -> 12000 | G12: =E12+F12 -> 13000 | H12: =المخزون!G11 -> Cash Only | I12: 0.85 | J12: =H12*I12 -> #VALUE! | K12: 1200 | L12: =(G12+K12)-J12 -> #VALUE!
A13: =المخزون!A12 -> E Golf | B13: =المخزون!C12 -> White | C13: =المخزون!D12 -> 0 | D13: =المخزون!F12 -> 2021 | E13: 1000 | F13: =المخزون!E12 -> 12300 | G13: =E13+F13 -> 13300 | H13: =المخزون!G12 -> 13500 | I13: 0.85 | J13: =H13*I13 -> 11475 | K13: 1200 | L13: =(G13+K13)-J13 -> 3025
A14: =المخزون!A13 -> LaVida | B14: =المخزون!C13 -> White | C14: =المخزون!D13 -> 0 | D14: =المخزون!F13 -> 2019 | E14: 1000 | F14: =المخزون!E13 -> 10700 | G14: =E14+F14 -> 11700 | H14: =المخزون!G13 -> 12000 | I14: 0.85 | J14: =H14*I14 -> 10200 | K14: 1200 | L14: =(G14+K14)-J14 -> 2700
A15: =المخزون!A14 -> LaVida | B15: =المخزون!C14 -> White | C15: =المخزون!D14 -> 0 | D15: =المخزون!F14 -> 2021 | E15: 1000 | F15: =المخزون!E14 -> 11500 | G15: =E15+F15 -> 12500 | H15: =المخزون!G14 -> 13500 | I15: 0.85 | J15: =H15*I15 -> 11475 | K15: 1200 | L15: =(G15+K15)-J15 -> 2225
A16: =المخزون!A15 -> Nano | B16: =المخزون!C15 -> White | C16: =المخزون!D15 -> ZERO | D16: =المخزون!F15 -> 2022 | E16: 1000 | F16: =المخزون!E15 -> 8250 | G16: =E16+F16 -> 9250 | H16: =المخزون!G15 -> 9500 | I16: 0.9 | J16: =H16*I16 -> 8550 | K16: 1200 | L16: =(G16+K16)-J16 -> 1900
A17: =المخزون!A16 -> Honda NS1 | B17: =المخزون!C16 -> blue | C17: =المخزون!D16 -> ZERO | D17: =المخزون!F16 -> 2023 | E17: 1000 | F17: =المخزون!E16 -> 16700 | G17: =E17+F17 -> 17700 | H17: =المخزون!G16 -> 18500 | I17: 0.9 | J17: =H17*I17 -> 16650 | K17: 1200 | L17: =(G17+K17)-J17 -> 2250
A18: =المخزون!A17 -> BYD seagall | B18: =المخزون!C17 -> Cream | C18: =المخزون!D17 -> ZERO | D18: =المخزون!F17 -> 2024 | E18: 1000 | F18: =المخزون!E17 -> 13250 | G18: =E18+F18 -> 14250 | H18: =المخزون!G17 -> 14500 | I18: 0.9 | J18: =H18*I18 -> 13050 | K18: 1200 | L18: =(G18+K18)-J18 -> 2400
A19: =المخزون!A18 -> toyota BZ3 | B19: =المخزون!C18 -> basali | C19: =المخزون!D18 -> 0 | D19: =المخزون!F18 -> 2023 | E19: 1000 | F19: =المخزون!E18 -> 18000 | G19: =E19+F19 -> 19000 | H19: =المخزون!G18 -> 20500 | I19: 0.85 | J19: =H19*I19 -> 17425 | K19: 1200 | L19: =(G19+K19)-J19 -> 2775
A20: =المخزون!A19 -> KIA EV5 | B20: =المخزون!C19 -> SKY BLUE | C20: =المخزون!D19 -> ZERO | D20: =المخزون!F19 -> 2023 | E20: 1000 | F20: =المخزون!E19 -> 22000 | G20: =E20+F20 -> 23000 | H20: =المخزون!G19 -> 25000 | I20: 0.9 | J20: =H20*I20 -> 22500 | K20: 1200 | L20: =(G20+K20)-J20 -> 1700
... A35: =المخزون!A34 -> Changan Eado | B35: =المخزون!C34 -> White | C35: =المخزون!D34 -> ZERO | D35: =المخزون!F34 -> 2023 | E35: 1000 | F35: =المخزون!E34 -> 14500 | G35: =E35+F35 -> 15500 | H35: =المخزون!G34 -> Cash Only | I35: 0.9 | J35: =H35*I35 -> #VALUE! | K35: 1200 | L35: =(G35+K35)-J35 -> #VALUE!
A36: =المخزون!A35 -> Changan Eado | B36: =المخزون!C35 -> White | C36: =المخزون!D35 -> ZERO | D36: =المخزون!F35 -> 2022 | E36: 1000 | F36: =المخزون!E35 -> 13000 | G36: =E36+F36 -> 14000 | H36: 14800 | I36: 0.9 | J36: =H36*I36 -> 13320 | K36: 1200 | L36: =(G36+K36)-J36 -> 1880
A37: =المخزون!A36 -> Song pro | B37: =المخزون!C36 -> Light Grey | C37: =المخزون!D36 -> ZERO | D37: =المخزون!F36 -> 2025 | E37: 1000 | F37: =المخزون!E36 -> 22000 | G37: =E37+F37 -> 23000 | H37: =المخزون!G36 -> 0 | I37: 0.85 | J37: =H37*I37 -> 0 | K37: 1200 | L37: =(G37+K37)-J37 -> 24200
A38: =المخزون!A37 -> BYD QUIN L | B38: =المخزون!C37 -> White | C38: =المخزون!D37 -> ZERO | D38: =المخزون!F37 -> 2025 | E38: 1000 | F38: =المخزون!E37 -> 0 | G38: =E38+F38 -> 1000 | H38: =المخزون!G37 -> 0 | I38: 0.9 | J38: =H38*I38 -> 0 | K38: 1200 | L38: =(G38+K38)-J38 -> 2200
A39: =المخزون!A38 -> 0 | B39: =المخزون!C38 -> 0 | C39: =المخزون!D38 -> 0 | D39: =المخزون!F38 -> 0 | E39: 1000 | F39: =المخزون!E38 -> 0 | G39: =E39+F39 -> 1000 | H39: =المخزون!G38 -> 0 | I39: 0.85 | J39: =H39*I39 -> 0 | K39: 1200 | L39: =(G39+K39)-J39 -> 2200
A40: =المخزون!A39 -> 0 | B40: =المخزون!C39 -> 0 | C40: =المخزون!D39 -> 0 | D40: =المخزون!F39 -> 0 | E40: 1000 | F40: =المخزون!E39 -> 0 | G40: =E40+F40 -> 1000 | H40: =المخزون!G39 -> 0 | I40: 0.9 | J40: =H40*I40 -> 0 | K40: 1200 | L40: =(G40+K40)-J40 -> 2200
A41: =المخزون!A40 -> 0 | B41: =المخزون!C40 -> 0 | C41: =المخزون!D40 -> 0 | D41: =المخزون!F40 -> 0 | E41: 1000 | F41: =المخزون!E40 -> 0 | G41: =E41+F41 -> 1000 | H41: =المخزون!G40 -> 0 | I41: 0.9 | J41: =H41*I41 -> 0 | K41: 1200 | L41: =(G41+K41)-J41 -> 2200
A42: =المخزون!A41 -> 0 | B42: =المخزون!C41 -> 0 | C42: =المخزون!D41 -> 0 | D42: =المخزون!F41 -> 0 | E42: 1000 | F42: =المخزون!E41 -> 0 | G42: =E42+F42 -> 1000 | H42: =المخزون!G41 -> 0 | I42: 0.9 | J42: =H42*I42 -> 0 | K42: 1200 | L42: =(G42+K42)-J42 -> 2200
A43: =المخزون!A42 -> 0 | B43: =المخزون!C42 -> 0 | C43: =المخزون!D42 -> 0 | D43: =المخزون!F42 -> 0 | E43: 1000 | F43: =المخزون!E42 -> 0 | G43: =E43+F43 -> 1000 | H43: =المخزون!G42 -> 0 | I43: 0.9 | J43: =H43*I43 -> 0 | K43: 1200 | L43: =(G43+K43)-J43 -> 2200
A44: =المخزون!A43 -> 0 | B44: =المخزون!C43 -> 0 | C44: =المخزون!D43 -> 0 | D44: =المخزون!F43 -> 0 | E44: 1000 | F44: =المخزون!E43 -> 0 | G44: =E44+F44 -> 1000 | H44: =المخزون!G43 -> 0 | I44: 0.9 | J44: =H44*I44 -> 0 | K44: 1200 | L44: =(G44+K44)-J44 -> 2200
A45: =المخزون!A44 -> 0 | B45: =المخزون!C44 -> 0 | C45: =المخزون!D44 -> 0 | D45: =المخزون!F44 -> 0 | E45: 1000 | F45: =المخزون!E44 -> 0 | G45: =E45+F45 -> 1000 | H45: =المخزون!G44 -> 0 | I45: 0.9 | J45: =H45*I45 -> 0 | K45: 1200 | L45: =(G45+K45)-J45 -> 2200
A46: =المخزون!A45 -> 0 | B46: =المخزون!C45 -> 0 | C46: =المخزون!D45 -> 0 | D46: =المخزون!F45 -> 0 | E46: 1000 | F46: =المخزون!E45 -> 0 | G46: =E46+F46 -> 1000 | H46: =المخزون!G45 -> 0 | I46: 0.9 | J46: =H46*I46 -> 0 | K46: 1200 | L46: =(G46+K46)-J46 -> 2200
A47: =المخزون!A46 -> 0 | B47: =المخزون!C36 -> Light Grey | C47: =المخزون!D46 -> 0 | D47: =المخزون!F46 -> 0 | E47: 1000 | F47: =المخزون!E46 -> 0 | G47: =E47+F47 -> 1000 | H47: =المخزون!G46 -> 0 | I47: 0.9 | J47: =H47*I47 -> 0 | K47: 1200 | L47: =(G47+K47)-J47 -> 2200
A48: =المخزون!A47 -> 0 | B48: =المخزون!C37 -> White | C48: =المخزون!D47 -> 0 | D48: =المخزون!F47 -> 0 | E48: 1000 | F48: =المخزون!E47 -> 0 | G48: =E48+F48 -> 1000 | H48: =المخزون!G47 -> 0 | I48: 0.9 | J48: =H48*I48 -> 0 | K48: 1200 | L48: =(G48+K48)-J48 -> 2200
A49: =المخزون!A48 -> 0 | B49: =المخزون!C38 -> 0 | C49: =المخزون!D48 -> 0 | D49: =المخزون!F48 -> 0 | E49: 1000 | F49: =المخزون!E48 -> 0 | G49: =E49+F49 -> 1000 | H49: =المخزون!G48 -> 0 | I49: 0.9 | J49: =H49*I49 -> 0 | K49: 1200 | L49: =(G49+K49)-J49 -> 2200
A50: =المخزون!A49 -> 0 | B50: =المخزون!C39 -> 0 | C50: =المخزون!D49 -> 0 | D50: =المخزون!F49 -> 0 | E50: 1000 | F50: =المخزون!E49 -> 0 | G50: =E50+F50 -> 1000 | H50: =المخزون!G49 -> 0 | I50: 0.9 | J50: =H50*I50 -> 0 | K50: 1200 | L50: =(G50+K50)-J50 -> 2200
A51: =المخزون!A50 -> 0 | B51: =المخزون!C40 -> 0 | C51: =المخزون!D50 -> 0 | D51: =المخزون!F50 -> 0 | E51: 1000 | F51: =المخزون!E50 -> 0 | G51: =E51+F51 -> 1000 | H51: =المخزون!G50 -> 0 | I51: 0.9 | J51: =H51*I51 -> 0 | K51: 1200 | L51: =(G51+K51)-J51 -> 2200
A52: =المخزون!A51 -> 0 | B52: =المخزون!C41 -> 0 | C52: =المخزون!D51 -> 0 | D52: =المخزون!F51 -> 0 | E52: 1000 | F52: =المخزون!E51 -> 0 | G52: =E52+F52 -> 1000 | H52: =المخزون!G51 -> 0 | I52: 0.9 | J52: =H52*I52 -> 0 | K52: 1200 | L52: =(G52+K52)-J52 -> 2200
A53: =المخزون!A52 -> 0 | B53: =المخزون!C42 -> 0 | C53: =المخزون!D52 -> 0 | D53: =المخزون!F42 -> 0 | E53: 1000 | F53: =المخزون!E52 -> 0 | G53: =E53+F53 -> 1000 | H53: =المخزون!G52 -> 0 | I53: 0.9 | J53: =H53*I53 -> 0 | K53: 1200 | L53: =(G53+K53)-J53 -> 2200
A54: =المخزون!A53 -> 0 | B54: =المخزون!C43 -> 0 | C54: =المخزون!D53 -> 0 | D54: =المخزون!F43 -> 0 | E54: 1000 | F54: =المخزون!E53 -> 0 | G54: =E54+F54 -> 1000 | H54: =المخزون!G53 -> 0 | I54: 0.9 | J54: =H54*I54 -> 0 | K54: 1200 | L54: =(G54+K54)-J54 -> 2200
A55: =المخزون!A54 -> 0 | B55: =المخزون!C44 -> 0 | C55: =المخزون!D54 -> 0 | D55: =المخزون!F44 -> 0 | E55: 1000 | F55: =المخزون!E54 -> 0 | G55: =E55+F55 -> 1000 | H55: =المخزون!G47 -> 0 | I55: 0.9 | J55: =H55*I55 -> 0 | K55: 1200 | L55: =(G55+K55)-J55 -> 2200
...

Sheet الكوثر
A1: الكوثر هوية | K1: 0.9 | M1: الكوثر اثبات دخل 7.75 | X1: الاوراق المطلوبة والاعتمادات
A2: TYPE/Name | B2: Model | C2: Target Margin | D2: Cost | E2: Price | F2: التخمين | G2: Rate | H2: المبلغ الممول | I2: المصاريف | J2: Total | K2: الدفعة المطلوبة | M2: TYPE/Name | N2: Model | O2: Target Margin | P2: Cost | Q2: Price | R2: التخمين | S2: Rate | T2: المبلغ الممول | U2: المصاريف | V2: Total | W2: الدفعة المطلوبة | X2: أي سيارة / تاجير تمويلي (ايجار ينتهي بالتملك)
A4: =المخزون!A3 -> BYD Dolphyn | B4: =المخزون!F3 -> 2022 | C4: 1000 | D4: =المخزون!E3 -> 12800 | E4: =D4+C4 -> 13800 | F4: =المخزون!H3 -> 13500 | G4: 0.9 | H4: =F4*G4 -> 12150 | I4: 850 | J4: =H4+I4 -> 13000 | K4: =(E4+I4)-H4 -> 2500 | M4: =المخزون!A3 -> BYD Dolphyn | N4: =المخزون!F3 -> 2022 | O4: 1000 | P4: =المخزون!E3 -> 12800 | Q4: =O4+P4 -> 13800 | R4: =المخزون!H3 -> 13500 | S4: 0.85 | T4: =R4*S4 -> 11475 | U4: 850 | V4: =T4+U4 -> 12325 | W4: =(Q4+U4)-T4 -> 3175 | X4: هوية
A5: =المخزون!A4 -> Hyundai Enciano | B5: =المخزون!F4 -> 2019 | C5: 1000 | D5: =المخزون!E4 -> 15500 | E5: =D5+C5 -> 16500 | F5: =المخزون!H4 -> Cash Only | G5: 0.9 | H5: =F5*G5 -> #VALUE! | I5: 850 | J5: =H5+I5 -> #VALUE! | K5: =(E5+I5)-H5 -> #VALUE! | M5: =المخزون!A4 -> Hyundai Enciano | N5: =المخزون!F4 -> 2019 | O5: 1000 | P5: =المخزون!E4 -> 15500 | Q5: =O5+P5 -> 16500 | R5: =المخزون!H4 -> Cash Only | S5: 0.85 | T5: =R5*S5 -> #VALUE! | U5: 850 | V5: =T5+U5 -> #VALUE! | W5: =(Q5+U5)-T5 -> #VALUE! | X5: كشف ضمان
A6: =المخزون!A5 -> Neta V | B6: =المخزون!F5 -> 2022 | C6: 1000 | D6: =المخزون!E5 -> 9700 | E6: =D6+C6 -> 10700 | F6: =المخزون!H5 -> 11000 | G6: 0.9 | H6: =F6*G6 -> 9900 | I6: 850 | J6: =H6+I6 -> 10750 | K6: =(E6+I6)-H6 -> 1650 | M6: =المخزون!A5 -> Neta V | N6: =المخزون!F5 -> 2022 | O6: 1000 | P6: =المخزون!E5 -> 9700 | Q6: =O6+P6 -> 10700 | R6: =المخزون!H5 -> 11000 | S6: 0.85 | T6: =R6*S6 -> 9350 | U6: 850 | V6: =T6+U6 -> 10200 | W6: =(Q6+U6)-T6 -> 2200 | X6: شهادة راتب
A7: =المخزون!A6 -> Neta V | B7: =المخزون!F6 -> 2021 | C7: 1000 | D7: =المخزون!E6 -> 8700 | E7: =D7+C7 -> 9700 | F7: =المخزون!H6 -> 9000 | G7: 0.9 | H7: =F7*G7 -> 8100 | I7: 850 | J7: =H7+I7 -> 8950 | K7: =(E7+I7)-H7 -> 2450 | M7: =المخزون!A6 -> Neta V | N7: =المخزون!F6 -> 2021 | O7: 1000 | P7: =المخزون!E6 -> 8700 | Q7: =O7+P7 -> 9700 | R7: =المخزون!H6 -> 9000 | S7: 0.85 | T7: =R7*S7 -> 7650 | U7: 850 | V7: =T7+U7 -> 8500 | W7: =(Q7+U7)-T7 -> 2900 | X7: كفيل انثى
A8: =المخزون!A7 -> Neta U / FULL | B8: =المخزون!F7 -> 2022 | C8: 1000 | D8: =المخزون!E7 -> 15000 | E8: =D8+C8 -> 16000 | F8: =المخزون!H7 -> 15500 | G8: 0.9 | H8: =F8*G8 -> 13950 | I8: 850 | J8: =H8+I8 -> 14800 | K8: =(E8+I8)-H8 -> 2900 | M8: =المخزون!A7 -> Neta U / FULL | N8: =المخزون!F7 -> 2022 | O8: 1000 | P8: =المخزون!E7 -> 15000 | Q8: =O8+P8 -> 16000 | R8: =المخزون!H7 -> 15500 | S8: 0.85 | T8: =R8*S8 -> 13175 | U8: 850 | V8: =T8+U8 -> 14025 | W8: =(Q8+U8)-T8 -> 3675 | X8: او كفيل عادي (يفضل انثى)
A9: =المخزون!A8 -> Neta Aya | B9: =المخزون!F8 -> 2023 | C9: 1000 | D9: =المخزون!E8 -> 10100 | E9: =D9+C9 -> 11100 | F9: =المخزون!H8 -> 11500 | G9: 0.9 | H9: =F9*G9 -> 10350 | I9: 850 | J9: =H9+I9 -> 11200 | K9: =(E9+I9)-H9 -> 1600 | M9: =المخزون!A8 -> Neta Aya | N9: =المخزون!F8 -> 2023 | O9: 1000 | P9: =المخزون!E8 -> 10100 | Q9: =O9+P9 -> 11100 | R9: =المخزون!H8 -> 11500 | S9: 0.85 | T9: =R9*S9 -> 9775 | U9: 850 | V9: =T9+U9 -> 10625 | W9: =(Q9+U9)-T9 -> 2175
A10: =المخزون!A9 -> Neta X | B10: =المخزون!F9 -> 2023 | C10: 1000 | D10: =المخزون!E9 -> 15500 | E10: =D10+C10 -> 16500 | F10: =المخزون!H9 -> 16500 | G10: 0.9 | H10: =F10*G10 -> 14850 | I10: 850 | J10: =H10+I10 -> 15700 | K10: =(E10+I10)-H10 -> 2500 | M10: =المخزون!A9 -> Neta X | N10: =المخزون!F9 -> 2023 | O10: 1000 | P10: =المخزون!E9 -> 15500 | Q10: =O10+P10 -> 16500 | R10: =المخزون!H9 -> 16500 | S10: 0.85 | T10: =R10*S10 -> 14025 | U10: 850 | V10: =T10+U10 -> 14875 | W10: =(Q10+U10)-T10 -> 3325 | X10: في حالة السجل التجاري يجب ان يكون السجل لسنة او اكثر ويرفق معه كشف حساب و رخصة مهن
A11: =المخزون!A10 -> BYD Yuan Plus | B11: =المخزون!F10 -> 2023 | C11: 1000 | D11: =المخزون!E10 -> 17800 | E11: =D11+C11 -> 18800 | F11: =المخزون!H10 -> 19000 | G11: 0.9 | H11: =F11*G11 -> 17100 | I11: 850 | J11: =H11+I11 -> 17950 | K11: =(E11+I11)-H11 -> 2550 | M11: =المخزون!A10 -> BYD Yuan Plus | N11: =المخزون!F10 -> 2023 | O11: 1000 | P11: =المخزون!E10 -> 17800 | Q11: =O11+P11 -> 18800 | R11: =المخزون!H10 -> 19000 | S11: 0.85 | T11: =R11*S11 -> 16150 | U11: 850 | V11: =T11+U11 -> 17000 | W11: =(Q11+U11)-T11 -> 3500
A12: =المخزون!A11 -> Nammi Box Dong Feng | B12: =المخزون!F11 -> 2023 | C12: 1000 | D12: =المخزون!E11 -> 12000 | E12: =D12+C12 -> 13000 | F12: =المخزون!H11 -> Cash Only | G12: 0.9 | H12: =F12*G12 -> #VALUE! | I12: 850 | J12: =H12+I12 -> #VALUE! | K12: =(E12+I12)-H12 -> #VALUE! | M12: =المخزون!A11 -> Nammi Box Dong Feng | N12: =المخزون!F11 -> 2023 | O12: 1000 | P12: =المخزون!E11 -> 12000 | Q12: =O12+P12 -> 13000 | R12: =المخزون!H11 -> Cash Only | S12: 0.85 | T12: =R12*S12 -> #VALUE! | U12: 850 | V12: =T12+U12 -> #VALUE! | W12: =(Q12+U12)-T12 -> #VALUE!
A13: =المخزون!A12 -> E Golf | B13: =المخزون!F12 -> 2021 | C13: 1000 | D13: =المخزون!E12 -> 12300 | E13: =D13+C13 -> 13300 | F13: =المخزون!H12 -> 13000 | G13: 0.9 | H13: =F13*G13 -> 11700 | I13: 850 | J13: =H13+I13 -> 12550 | K13: =(E13+I13)-H13 -> 2450 | M13: =المخزون!A12 -> E Golf | N13: =المخزون!F12 -> 2021 | O13: 1000 | P13: =المخزون!E12 -> 12300 | Q13: =O13+P13 -> 13300 | R13: =المخزون!H12 -> 13000 | S13: 0.85 | T13: =R13*S13 -> 11050 | U13: 850 | V13: =T13+U13 -> 11900 | W13: =(Q13+U13)-T13 -> 3100
A14: =المخزون!A13 -> LaVida | B14: =المخزون!F13 -> 2019 | C14: 1000 | D14: =المخزون!E13 -> 10700 | E14: =D14+C14 -> 11700 | F14: =المخزون!H13 -> 11700 | G14: 0.9 | H14: =F14*G14 -> 10530 | I14: 850 | J14: =H14+I14 -> 11380 | K14: =(E14+I14)-H14 -> 2020 | M14: =المخزون!A13 -> LaVida | N14: =المخزون!F13 -> 2019 | O14: 1000 | P14: =المخزون!E13 -> 10700 | Q14: =O14+P14 -> 11700 | R14: =المخزون!H13 -> 11700 | S14: 0.85 | T14: =R14*S14 -> 9945 | U14: 850 | V14: =T14+U14 -> 10795 | W14: =(Q14+U14)-T14 -> 2605
A15: =المخزون!A14 -> LaVida | B15: =المخزون!F14 -> 2021 | C15: 1000 | D15: =المخزون!E14 -> 11500 | E15: =D15+C15 -> 12500 | F15: =المخزون!H14 -> 13000 | G15: 0.9 | H15: =F15*G15 -> 11700 | I15: 850 | J15: =H15+I15 -> 12550 | K15: =(E15+I15)-H15 -> 1650 | M15: =المخزون!A14 -> LaVida | N15: =المخزون!F14 -> 2021 | O15: 1000 | P15: =المخزون!E14 -> 11500 | Q15: =O15+P15 -> 12500 | R15: =المخزون!H14 -> 13000 | S15: 0.85 | T15: =R15*S15 -> 11050 | U15: 850 | V15: =T15+U15 -> 11900 | W15: =(Q15+U15)-T15 -> 2300
A16: =المخزون!A15 -> Nano | B16: =المخزون!F15 -> 2022 | C16: 1000 | D16: =المخزون!E15 -> 8250 | E16: =D16+C16 -> 9250 | F16: =المخزون!H15 -> 9000 | G16: 0.9 | H16: =F16*G16 -> 8100 | I16: 850 | J16: =H16+I16 -> 8950 | K16: =(E16+I16)-H16 -> 2000 | M16: =المخزون!A15 -> Nano | N16: =المخزون!F15 -> 2022 | O16: 1000 | P16: =المخزون!E15 -> 8250 | Q16: =O16+P16 -> 9250 | R16: =المخزون!H15 -> 9000 | S16: 0.85 | T16: =R16*S16 -> 7650 | U16: 850 | V16: =T16+U16 -> 8500 | W16: =(Q16+U16)-T16 -> 2450
A17: =المخزون!A16 -> Honda NS1 | B17: =المخزون!F16 -> 2023 | C17: 1000 | D17: =المخزون!E16 -> 16700 | E17: =D17+C17 -> 17700 | F17: =المخزون!H16 -> 17500 | G17: 0.9 | H17: =F17*G17 -> 15750 | I17: 850 | J17: =H17+I17 -> 16600 | K17: =(E17+I17)-H17 -> 2800 | M17: =المخزون!A16 -> Honda NS1 | N17: =المخزون!F16 -> 2023 | O17: 1000 | P17: =المخزون!E16 -> 16700 | Q17: =O17+P17 -> 17700 | R17: =المخزون!H16 -> 17500 | S17: 0.85 | T17: =R17*S17 -> 14875 | U17: 850 | V17: =T17+U17 -> 15725 | W17: =(Q17+U17)-T17 -> 3675
A18: =المخزون!A17 -> BYD seagall | B18: =المخزون!F17 -> 2024 | C18: 1000 | D18: =المخزون!E17 -> 13250 | E18: =D18+C18 -> 14250 | F18: =المخزون!H17 -> 14500 | G18: 0.9 | H18: =F18*G18 -> 13050 | I18: 850 | J18: =H18+I18 -> 13900 | K18: =(E18+I18)-H18 -> 2050 | M18: =المخزون!A17 -> BYD seagall | N18: =المخزون!F17 -> 2024 | O18: 1000 | P18: =المخزون!E17 -> 13250 | Q18: =O18+P18 -> 14250 | R18: =المخزون!H17 -> 14500 | S18: 0.85 | T18: =R18*S18 -> 12325 | U18: 850 | V18: =T18+U18 -> 13175 | W18: =(Q18+U18)-T18 -> 2775
A19: =المخزون!A18 -> toyota BZ3 | B19: =المخزون!F18 -> 2023 | C19: 1000 | D19: =المخزون!E18 -> 18000 | E19: =D19+C19 -> 19000 | F19: =المخزون!H18 -> 20000 | G19: 0.9 | H19: =F19*G19 -> 18000 | I19: 850 | J19: =H19+I19 -> 18850 | K19: =(E19+I19)-H19 -> 1850 | M19: =المخزون!A18 -> toyota BZ3 | N19: =المخزون!F18 -> 2023 | O19: 1000 | P19: =المخزون!E18 -> 18000 | Q19: =O19+P19 -> 19000 | R19: =المخزون!H18 -> 20000 | S19: 0.85 | T19: =R19*S19 -> 17000 | U19: 850 | V19: =T19+U19 -> 17850 | W19: =(Q19+U19)-T19 -> 2850
A20: =المخزون!A19 -> KIA EV5 | B20: =المخزون!F19 -> 2023 | C20: 1000 | D20: =المخزون!E19 -> 22000 | E20: =D20+C20 -> 23000 | F20: =المخزون!H19 -> 24000 | G20: 0.9 | H20: =F20*G20 -> 21600 | I20: 850 | J20: =H20+I20 -> 22450 | K20: =(E20+I20)-H20 -> 2250 | M20: =المخزون!A19 -> KIA EV5 | N20: =المخزون!F19 -> 2023 | O20: 1000 | P20: =المخزون!E19 -> 22000 | Q20: =O20+P20 -> 23000 | R20: =المخزون!H19 -> 24000 | S20: 0.85 | T20: =R20*S20 -> 20400 | U20: 850 | V20: =T20+U20 -> 21250 | W20: =(Q20+U20)-T20 -> 3450
A21: =المخزون!A20 -> QUIN BYD EV | B21: =المخزون!F20 -> 2023 | C21: 1000 | D21: =المخزون!E20 -> 13000 | E21: =D21+C21 -> 14000 | F21: =المخزون!H20 -> 14500 | G21: 0.9 | H21: =F21*G21 -> 13050 | I21: 850 | J21: =H21+I21 -> 13900 | K21: =(E21+I21)-H21 -> 1800 | M21: =المخزون!A20 -> QUIN BYD EV | N21: =المخزون!F20 -> 2023 | O21: 1000 | P21: =المخزون!E20 -> 13000 | Q21: =O21+P21 -> 14000 | R21: =المخزون!H20 -> 14500 | S21: 0.85 | T21: =R21*S21 -> 12325 | U21: 850 | V21: =T21+U21 -> 13175 | W21: =(Q21+U21)-T21 -> 2525
A22: =المخزون!A21 -> BYD E2 20 305 | B22: =المخزون!F21 -> 2020 | C22: 1000 | D22: =المخزون!E21 -> 11300 | E22: =D22+C22 -> 12300 | F22: =المخزون!H21 -> 12000 | G22: 0.9 | H22: =F22*G22 -> 10800 | I22: 850 | J22: =H22+I22 -> 11650 | K22: =(E22+I22)-H22 -> 2350 | M22: =المخزون!A21 -> BYD E2 20 305 | N22: =المخزون!F21 -> 2020 | O22: 1000 | P22: =المخزون!E21 -> 11300 | Q22: =O22+P22 -> 12300 | R22: =المخزون!H21 -> 12000 | S22: 0.85 | T22: =R22*S22 -> 10200 | U22: 850 | V22: =T22+U22 -> 11050 | W22: =(Q22+U22)-T22 -> 2950
... A40: =المخزون!A39 -> 0 | B40: =المخزون!F39 -> 0 | C40: 1000 | D40: =المخزون!E39 -> 0 | E40: =D40+C40 -> 1000 | F40: =المخزون!H39 -> 0 | G40: 0.9 | H40: =F40*G40 -> 0 | I40: 850 | J40: =H40+I40 -> 850 | K40: =(E40+I40)-H40 -> 1850 | M40: =المخزون!A39 -> 0 | N40: =المخزون!F39 -> 0 | O40: 1000 | P40: =المخزون!E39 -> 0 | Q40: =O40+P40 -> 1000 | R40: =المخزون!H39 -> 0 | S40: 0.85 | T40: =R40*S40 -> 0 | U40: 850 | V40: =T40+U40 -> 850 | W40: =(Q40+U40)-T40 -> 1850
A41: =المخزون!A40 -> 0 | B41: =المخزون!F40 -> 0 | C41: 1000 | D41: =المخزون!E40 -> 0 | E41: =D41+C41 -> 1000 | F41: =المخزون!H40 -> 0 | G41: 0.9 | H41: =F41*G41 -> 0 | I41: 850 | J41: =H41+I41 -> 850 | K41: =(E41+I41)-H41 -> 1850 | M41: =المخزون!A40 -> 0 | N41: =المخزون!F30 -> 2024 | O41: 1000 | P41: =المخزون!E40 -> 0 | Q41: =O41+P41 -> 1000 | R41: =المخزون!H40 -> 0 | S41: 0.85 | T41: =R41*S41 -> 0 | U41: 850 | V41: =T41+U41 -> 850 | W41: =(Q41+U41)-T41 -> 1850
A42: =المخزون!A41 -> 0 | B42: =المخزون!F41 -> 0 | C42: 1000 | D42: =المخزون!E41 -> 0 | E42: =D42+C42 -> 1000 | F42: =المخزون!H41 -> 0 | G42: 0.9 | H42: =F42*G42 -> 0 | I42: 850 | J42: =H42+I42 -> 850 | K42: =(E42+I42)-H42 -> 1850 | M42: =المخزون!A41 -> 0 | N42: =المخزون!F31 -> 2022 | O42: 1000 | P42: =المخزون!E41 -> 0 | Q42: =O42+P42 -> 1000 | R42: =المخزون!H41 -> 0 | S42: 0.85 | T42: =R42*S42 -> 0 | U42: 850 | V42: =T42+U42 -> 850 | W42: =(Q42+U42)-T42 -> 1850
A43: =المخزون!A42 -> 0 | B43: =المخزون!F42 -> 0 | C43: 1000 | D43: =المخزون!E42 -> 0 | E43: =D43+C43 -> 1000 | F43: =المخزون!H42 -> 0 | G43: 0.9 | H43: =F43*G43 -> 0 | I43: 850 | J43: =H43+I43 -> 850 | K43: =(E43+I43)-H43 -> 1850 | M43: =المخزون!A42 -> 0 | N43: =المخزون!F32 -> 2026 | O43: 1000 | P43: =المخزون!E42 -> 0 | Q43: =O43+P43 -> 1000 | R43: =المخزون!H42 -> 0 | S43: 0.85 | T43: =R43*S43 -> 0 | U43: 850 | V43: =T43+U43 -> 850 | W43: =(Q43+U43)-T43 -> 1850
A44: =المخزون!A43 -> 0 | B44: =المخزون!F43 -> 0 | C44: 1000 | D44: =المخزون!E43 -> 0 | E44: =D44+C44 -> 1000 | F44: =المخزون!H43 -> 0 | G44: 0.9 | H44: =F44*G44 -> 0 | I44: 850 | J44: =H44+I44 -> 850 | K44: =(E44+I44)-H44 -> 1850 | M44: =المخزون!A43 -> 0 | N44: =المخزون!F33 -> 2026 | O44: 1000 | P44: =المخزون!E43 -> 0 | Q44: =O44+P44 -> 1000 | R44: =المخزون!H43 -> 0 | S44: 0.85 | T44: =R44*S44 -> 0 | U44: 850 | V44: =T44+U44 -> 850 | W44: =(Q44+U44)-T44 -> 1850
A45: =المخزون!A44 -> 0 | B45: =المخزون!F44 -> 0 | C45: 1000 | D45: =المخزون!E44 -> 0 | E45: =D45+C45 -> 1000 | F45: =المخزون!H44 -> 0 | G45: 0.9 | H45: =F45*G45 -> 0 | I45: 850 | J45: =H45+I45 -> 850 | K45: =(E45+I45)-H45 -> 1850 | M45: =المخزون!A44 -> 0 | N45: =المخزون!F34 -> 2023 | O45: 1000 | P45: =المخزون!E44 -> 0 | Q45: =O45+P45 -> 1000 | R45: =المخزون!H44 -> 0 | S45: 0.85 | T45: =R45*S45 -> 0 | U45: 850 | V45: =T45+U45 -> 850 | W45: =(Q45+U45)-T45 -> 1850
A46: =المخزون!A45 -> 0 | B46: =المخزون!F45 -> 0 | C46: 1000 | D46: =المخزون!E45 -> 0 | E46: =D46+C46 -> 1000 | F46: =المخزون!H45 -> 0 | G46: 0.9 | H46: =F46*G46 -> 0 | I46: 850 | J46: =H46+I46 -> 850 | K46: =(E46+I46)-H46 -> 1850 | M46: =المخزون!A45 -> 0 | N46: =المخزون!F35 -> 2022 | O46: 1000 | P46: =المخزون!E45 -> 0 | Q46: =O46+P46 -> 1000 | R46: =المخزون!H45 -> 0 | S46: 0.85 | T46: =R46*S46 -> 0 | U46: 850 | V46: =T46+U46 -> 850 | W46: =(Q46+U46)-T46 -> 1850
A47: =المخزون!A46 -> 0 | B47: =المخزون!F46 -> 0 | C47: 1000 | D47: =المخزون!E46 -> 0 | E47: =D47+C47 -> 1000 | F47: =المخزون!H46 -> 0 | G47: 0.9 | H47: =F47*G47 -> 0 | I47: 850 | J47: =H47+I47 -> 850 | K47: =(E47+I47)-H47 -> 1850 | M47: =المخزون!A46 -> 0 | N47: =المخزون!F36 -> 2025 | O47: 1000 | P47: =المخزون!E46 -> 0 | Q47: =O47+P47 -> 1000 | R47: =المخزون!H46 -> 0 | S47: 0.85 | T47: =R47*S47 -> 0 | U47: 850 | V47: =T47+U47 -> 850 | W47: =(Q47+U47)-T47 -> 1850
A48: =المخزون!A47 -> 0 | B48: =المخزون!F47 -> 0 | C48: 1000 | D48: =المخزون!E47 -> 0 | E48: =D48+C48 -> 1000 | F48: =المخزون!H47 -> 0 | G48: 0.9 | H48: =F48*G48 -> 0 | I48: 850 | J48: =H48+I48 -> 850 | K48: =(E48+I48)-H48 -> 1850 | M48: =المخزون!A47 -> 0 | N48: =المخزون!F37 -> 2025 | O48: 1000 | P48: =المخزون!E47 -> 0 | Q48: =O48+P48 -> 1000 | R48: =المخزون!H47 -> 0 | S48: 0.85 | T48: =R48*S48 -> 0 | U48: 850 | V48: =T48+U48 -> 850 | W48: =(Q48+U48)-T48 -> 1850
A49: =المخزون!A48 -> 0 | B49: =المخزون!F48 -> 0 | C49: 1000 | D49: =المخزون!E48 -> 0 | E49: =D49+C49 -> 1000 | F49: =المخزون!H48 -> 0 | G49: 0.9 | H49: =F49*G49 -> 0 | I49: 850 | J49: =H49+I49 -> 850 | K49: =(E49+I49)-H49 -> 1850 | M49: =المخزون!A48 -> 0 | N49: =المخزون!F38 -> 0 | O49: 1000 | P49: =المخزون!E48 -> 0 | Q49: =O49+P49 -> 1000 | R49: =المخزون!H48 -> 0 | S49: 0.85 | T49: =R49*S49 -> 0 | U49: 850 | V49: =T49+U49 -> 850 | W49: =(Q49+U49)-T49 -> 1850
A50: =المخزون!A49 -> 0 | B50: =المخزون!F49 -> 0 | C50: 1000 | D50: =المخزون!E49 -> 0 | E50: =D50+C50 -> 1000 | F50: =المخزون!H49 -> 0 | G50: 0.9 | H50: =F50*G50 -> 0 | I50: 850 | J50: =H50+I50 -> 850 | K50: =(E50+I50)-H50 -> 1850 | M50: =المخزون!A49 -> 0 | N50: =المخزون!F39 -> 0 | O50: 1000 | P50: =المخزون!E49 -> 0 | Q50: =O50+P50 -> 1000 | R50: =المخزون!H49 -> 0 | S50: 0.85 | T50: =R50*S50 -> 0 | U50: 850 | V50: =T50+U50 -> 850 | W50: =(Q50+U50)-T50 -> 1850
A51: =المخزون!A50 -> 0 | B51: =المخزون!F50 -> 0 | C51: 1000 | D51: =المخزون!E50 -> 0 | E51: =D51+C51 -> 1000 | F51: =المخزون!H50 -> 0 | G51: 0.9 | H51: =F51*G51 -> 0 | I51: 850 | J51: =H51+I51 -> 850 | K51: =(E51+I51)-H51 -> 1850 | M51: =المخزون!A50 -> 0 | N51: =المخزون!F40 -> 0 | O51: 1000 | P51: =المخزون!E40 -> 0 | Q51: =O51+P51 -> 1000 | R51: =المخزون!H50 -> 0 | S51: 0.85 | T51: =R51*S51 -> 0 | U51: 850 | V51: =T51+U51 -> 850 | W51: =(Q51+U51)-T51 -> 1850
A52: =المخزون!A51 -> 0 | B52: =المخزون!F51 -> 0 | C52: 1000 | D52: =المخزون!E51 -> 0 | E52: =D52+C52 -> 1000 | F52: =المخزون!H51 -> 0 | G52: 0.9 | H52: =F52*G52 -> 0 | I52: 850 | J52: =H52+I52 -> 850 | K52: =(E52+I52)-H52 -> 1850 | M52: =المخزون!A51 -> 0 | N52: =المخزون!F41 -> 0 | O52: 1000 | P52: =المخزون!E41 -> 0 | Q52: =O52+P52 -> 1000 | R52: =المخزون!H51 -> 0 | S52: 0.85 | T52: =R52*S52 -> 0 | U52: 850 | V52: =T52+U52 -> 850 | W52: =(Q52+U52)-T52 -> 1850
A53: =المخزون!A52 -> 0 | B53: =المخزون!F52 -> 0 | C53: 1000 | D53: =المخزون!E52 -> 0 | E53: =D53+C53 -> 1000 | F53: =المخزون!H52 -> 0 | G53: 0.9 | H53: =F53*G53 -> 0 | I53: 850 | J53: =H53+I53 -> 850 | K53: =(E53+I53)-H53 -> 1850 | M53: =المخزون!A52 -> 0 | N53: =المخزون!F42 -> 0 | O53: 1000 | P53: =المخزون!E42 -> 0 | Q53: =O53+P53 -> 1000 | R53: =المخزون!H52 -> 0 | S53: 0.85 | T53: =R53*S53 -> 0 | U53: 850 | V53: =T53+U53 -> 850 | W53: =(Q53+U53)-T53 -> 1850
A54: =المخزون!A53 -> 0 | B54: =المخزون!F53 -> 0 | C54: 1000 | D54: =المخزون!E53 -> 0 | E54: =D54+C54 -> 1000 | F54: =المخزون!H53 -> 0 | G54: 0.9 | H54: =F54*G54 -> 0 | I54: 850 | J54: =H54+I54 -> 850 | K54: =(E54+I54)-H54 -> 1850 | M54: =المخزون!A53 -> 0 | N54: =المخزون!F43 -> 0 | O54: 1000 | P54: =المخزون!E43 -> 0 | Q54: =O54+P54 -> 1000 | R54: =المخزون!H53 -> 0 | S54: 0.85 | T54: =R54*S54 -> 0 | U54: 850 | V54: =T54+U54 -> 850 | W54: =(Q54+U54)-T54 -> 1850
A55: =المخزون!A54 -> 0 | B55: =المخزون!F54 -> 0 | C55: 1000 | D55: =المخزون!E54 -> 0 | E55: =D55+C55 -> 1000 | F55: =المخزون!H54 -> 0 | G55: 0.9 | H55: =F55*G55 -> 0 | I55: 850 | J55: =H55+I55 -> 850 | K55: =(E55+I55)-H55 -> 1850 | M55: =المخزون!A54 -> 0 | N55: =المخزون!F44 -> 0 | O55: 1000 | P55: =المخزون!E44 -> 0 | Q55: =O55+P55 -> 1000 | R55: =المخزون!H54 -> 0 | S55: 0.85 | T55: =R55*S55 -> 0 | U55: 850 | V55: =T55+U55 -> 850 | W55: =(Q55+U55)-T55 -> 1850
A56: =المخزون!A55 -> 0 | B56: =المخزون!F55 -> 0 | C56: 1000 | D56: =المخزون!E55 -> 0 | E56: =D56+C56 -> 1000 | F56: =المخزون!H55 -> 0 | G56: 0.9 | H56: =F56*G56 -> 0 | I56: 850 | J56: =H56+I56 -> 850 | K56: =(E56+I56)-H56 -> 1850 | M56: =المخزون!A45 -> 0 | N56: =المخزون!F45 -> 0 | O56: 1000 | P56: =المخزون!E45 -> 0 | Q56: =O56+P56 -> 1000 | R56: =المخزون!H55 -> 0 | S56: 0.85 | T56: =R56*S56 -> 0 | U56: 850 | V56: =T56+U56 -> 850 | W56: =(Q56+U56)-T56 -> 1850
A57: =المخزون!A56 -> 0 | B57: =المخزون!F56 -> 0 | C57: 1000 | D57: =المخزون!E56 -> 0 | E57: =D57+C57 -> 1000 | F57: =المخزون!H56 -> 0 | G57: 0.9 | H57: =F57*G57 -> 0 | I57: 850 | J57: =H57+I57 -> 850 | K57: =(E57+I57)-H57 -> 1850 | M57: =المخزون!A46 -> 0 | N57: =المخزون!F46 -> 0 | O57: 1000 | P57: =المخزون!E46 -> 0 | Q57: =O57+P57 -> 1000 | R57: =المخزون!H56 -> 0 | S57: 0.85 | T57: =R57*S57 -> 0 | U57: 850 | V57: =T57+U57 -> 850 | W57: =(Q57+U57)-T57 -> 1850
A58: =المخزون!A57 -> 0 | B58: =المخزون!F45 -> 0 | C58: 1000 | D58: =المخزون!E47 -> 0 | E58: =D58+C58 -> 1000 | F58: =المخزون!H57 -> 0 | G58: 0.9 | H58: =F58*G58 -> 0 | I58: 850 | J58: =H58+I58 -> 850 | K58: =(E58+I58)-H58 -> 1850 | M58: =المخزون!A47 -> 0 | N58: =المخزون!F47 -> 0 | O58: 1000 | P58: =المخزون!E47 -> 0 | Q58: =O58+P58 -> 1000 | S58: 0.85 | T58: =R58*S58 -> 0 | U58: 850 | V58: =T58+U58 -> 850 | W58: =(Q58+U58)-T58 -> 1850
...

Sheet بندار
A1: بندار | M1: Zero 90 | N1: الاوراق المطلوبة والاعتمادات
A2: TYPE/Name | C2: Model | D2: Target Margin | E2: Cost | F2: Price | G2: التخمين | H2: Rate | I2: المبلغ الممول | J2: المصاريف | K2: Total | L2: الدفعة المطلوبة | N2: تعتمد سيارات مؤسسة الرشاد / بدون كفيل 80% / تنازل و رهن
A4: =المخزون!A3 -> BYD Dolphyn | B4: =المخزون!D3 -> 0 | C4: =المخزون!F3 -> 2022 | D4: 1000 | E4: =المخزون!E3 -> 12800 | F4: =D4+E4 -> 13800 | G4: =المخزون!I3 -> 14300 | H4: 0.9 | I4: =G4*H4 -> 12870 | J4: 1200 | K4: =I4+J4 -> 14070 | L4: =(F4+J4)-I4 -> 2130 | N4: هوية
A5: =المخزون!A4 -> Hyundai Enciano | B5: =المخزون!D4 -> 0 | C5: =المخزون!F4 -> 2019 | D5: 1000 | E5: =المخزون!E4 -> 15500 | F5: =D5+E5 -> 16500 | G5: =المخزون!I4 -> Cash Only | H5: 0.9 | I5: =G5*H5 -> #VALUE! | J5: 1200 | K5: =I5+J5 -> #VALUE! | L5: =(F5+J5)-I5 -> #VALUE! | N5: فاتورة كهرباء
A6: =المخزون!A5 -> Neta V | B6: =المخزون!D5 -> 0 | C6: =المخزون!F5 -> 2022 | D6: 1000 | E6: =المخزون!E5 -> 9700 | F6: =D6+E6 -> 10700 | G6: =المخزون!I5 -> 0 | H6: 0.9 | I6: =G6*H6 -> 0 | J6: 1200 | K6: =I6+J6 -> 1200 | L6: =(F6+J6)-I6 -> 11900 | N6: دفتر عائلة
A7: =المخزون!A6 -> Neta V | B7: =المخزون!D6 -> 0 | C7: =المخزون!F6 -> 2021 | D7: 1000 | E7: =المخزون!E6 -> 8700 | F7: =D7+E7 -> 9700 | G7: =المخزون!I6 -> 9000 | H7: 0.9 | I7: =G7*H7 -> 8100 | J7: 1200 | K7: =I7+J7 -> 9300 | L7: =(F7+J7)-I7 -> 2800 | N7: عقد ايجار
A8: =المخزون!A7 -> Neta U / FULL | B8: =المخزون!D7 -> 0 | C8: =المخزون!F7 -> 2022 | D8: 1000 | E8: =المخزون!E7 -> 15000 | F8: =D8+E8 -> 16000 | G8: =المخزون!I7 -> 16000 | H8: 0.9 | I8: =G8*H8 -> 14400 | J8: 1200 | K8: =I8+J8 -> 15600 | L8: =(F8+J8)-I8 -> 2800
A9: =المخزون!A8 -> Neta Aya | B9: =المخزون!D8 -> 0 | C9: =المخزون!F8 -> 2023 | D9: 1000 | E9: =المخزون!E8 -> 10100 | F9: =D9+E9 -> 11100 | G9: =المخزون!I8 -> 12000 | H9: 0.9 | I9: =G9*H9 -> 10800 | J9: 1200 | K9: =I9+J9 -> 12000 | L9: =(F9+J9)-I9 -> 1500 | N9: في حال كا العمل على تطبيقات التوصيل يطلب كفيل درجة اولى وكفيل عادي
A10: =المخزون!A9 -> Neta X | B10: =المخزون!D9 -> 0 | C10: =المخزون!F9 -> 2023 | D10: 1000 | E10: =المخزون!E9 -> 15500 | F10: =D10+E10 -> 16500 | G10: =المخزون!I9 -> 17300 | H10: 0.9 | I10: =G10*H10 -> 15570 | J10: 1200 | K10: =I10+J10 -> 16770 | L10: =(F10+J10)-I10 -> 2130
A11: =المخزون!A10 -> BYD Yuan Plus | B11: =المخزون!D10 -> 0 | C11: =المخزون!F10 -> 2023 | D11: 1000 | E11: =المخزون!E10 -> 17800 | F11: =D11+E11 -> 18800 | G11: =المخزون!I10 -> 19000 | H11: 0.9 | I11: =G11*H11 -> 17100 | J11: 1200 | K11: =I11+J11 -> 18300 | L11: =(F11+J11)-I11 -> 2900
A12: =المخزون!A11 -> Nammi Box Dong Feng | B12: =المخزون!D11 -> 0 | C12: =المخزون!F11 -> 2023 | D12: 1000 | E12: =المخزون!E11 -> 12000 | F12: =D12+E12 -> 13000 | G12: =المخزون!I11 -> Cash Only | H12: 0.9 | I12: =G12*H12 -> #VALUE! | J12: 1200 | K12: =I12+J12 -> #VALUE! | L12: =(F12+J12)-I12 -> #VALUE!
A13: =المخزون!A12 -> E Golf | B13: =المخزون!D12 -> 0 | C13: =المخزون!F12 -> 2021 | D13: 1000 | E13: =المخزون!E12 -> 12300 | F13: =D13+E13 -> 13300 | G13: =المخزون!I12 -> 13000 | H13: 0.9 | I13: =G13*H13 -> 11700 | J13: 1200 | K13: =I13+J13 -> 12900 | L13: =(F13+J13)-I13 -> 2800
A14: =المخزون!A13 -> LaVida | B14: =المخزون!D13 -> 0 | C14: =المخزون!F13 -> 2019 | D14: 1000 | E14: =المخزون!E13 -> 10700 | F14: =D14+E14 -> 11700 | G14: =المخزون!I13 -> 11700 | H14: 0.9 | I14: =G14*H14 -> 10530 | J14: 1200 | K14: =I14+J14 -> 11730 | L14: =(F14+J14)-I14 -> 2370
A15: =المخزون!A14 -> LaVida | B15: =المخزون!D14 -> 0 | C15: =المخزون!F14 -> 2021 | D15: 1000 | E15: =المخزون!E14 -> 11500 | F15: =D15+E15 -> 12500 | G15: =المخزون!I14 -> 13000 | H15: 0.9 | I15: =G15*H15 -> 11700 | J15: 1200 | K15: =I15+J15 -> 12900 | L15: =(F15+J15)-I15 -> 2000
A16: =المخزون!A15 -> Nano | B16: =المخزون!D15 -> ZERO | C16: =المخزون!F15 -> 2022 | D16: 1000 | E16: =المخزون!E15 -> 8250 | F16: =D16+E16 -> 9250 | G16: =المخزون!I15 -> 9000 | H16: 0.9 | I16: =G16*H16 -> 8100 | J16: 1200 | K16: =I16+J16 -> 9300 | L16: =(F16+J16)-I16 -> 2350
A17: =المخزون!A16 -> Honda NS1 | B17: =المخزون!D16 -> ZERO | C17: =المخزون!F16 -> 2023 | D17: 1000 | E17: =المخزون!E16 -> 16700 | F17: =D17+E17 -> 17700 | G17: =المخزون!I16 -> 18000 | H17: 0.9 | I17: =G17*H17 -> 16200 | J17: 1200 | K17: =I17+J17 -> 17400 | L17: =(F17+J17)-I17 -> 2700
A18: =المخزون!A17 -> BYD seagall | B18: =المخزون!D17 -> ZERO | C18: =المخزون!F17 -> 2024 | D18: 1000 | E18: =المخزون!E17 -> 13250 | F18: =D18+E18 -> 14250 | G18: =المخزون!I17 -> 14500 | H18: 0.9 | I18: =G18*H18 -> 13050 | J18: 1200 | K18: =I18+J18 -> 14250 | L18: =(F18+J18)-I18 -> 2400
A19: =المخزون!A18 -> toyota BZ3 | B19: =المخزون!D18 -> 0 | C19: =المخزون!F18 -> 2023 | D19: 1000 | E19: =المخزون!E18 -> 18000 | F19: =D19+E19 -> 19000 | G19: =المخزون!I18 -> 20000 | H19: 0.9 | I19: =G19*H19 -> 18000 | J19: 1200 | K19: =I19+J19 -> 19200 | L19: =(F19+J19)-I19 -> 2200
A20: =المخزون!A19 -> KIA EV5 | B20: =المخزون!D19 -> ZERO | C20: =المخزون!F19 -> 2023 | D20: 1000 | E20: =المخزون!E19 -> 22000 | F20: =D20+E20 -> 23000 | G20: =المخزون!I19 -> 25000 | H20: 0.9 | I20: =G20*H20 -> 22500 | J20: 1200 | K20: =I20+J20 -> 23700 | L20: =(F20+J20)-I20 -> 1700
A21: =المخزون!A20 -> QUIN BYD EV | B21: =المخزون!D20 -> ZERO | C21: =المخزون!F20 -> 2023 | D21: 1000 | E21: =المخزون!E20 -> 13000 | F21: =D21+E21 -> 14000 | G21: =المخزون!I20 -> 14500 | H21: 0.9 | I21: =G21*H21 -> 13050 | J21: 1200 | K21: =I21+J21 -> 14250 | L21: =(F21+J21)-I21 -> 2150
... A40: =المخزون!A39 -> 0 | B40: =المخزون!D39 -> 0 | C40: =المخزون!F39 -> 0 | D40: 1000 | E40: =المخزون!E39 -> 0 | F40: =D40+E40 -> 1000 | G40: =المخزون!I39 -> 0 | H40: 0.9 | I40: =G40*H40 -> 0 | J40: 1200 | K40: =I40+J40 -> 1200 | L40: =(F40+J40)-I40 -> 2200
A41: =المخزون!A40 -> 0 | B41: =المخزون!D40 -> 0 | C41: =المخزون!F30 -> 2024 | D41: 1000 | E41: =المخزون!E40 -> 0 | F41: =D41+E41 -> 1000 | G41: =المخزون!I40 -> 0 | H41: 0.9 | I41: =G41*H41 -> 0 | J41: 1200 | K41: =I41+J41 -> 1200 | L41: =(F41+J41)-I41 -> 2200
A42: =المخزون!A41 -> 0 | B42: =المخزون!D41 -> 0 | C42: =المخزون!F31 -> 2022 | D42: 1000 | E42: =المخزون!E41 -> 0 | F42: =D42+E42 -> 1000 | G42: =المخزون!I41 -> 0 | H42: 0.9 | I42: =G42*H42 -> 0 | J42: 1200 | K42: =I42+J42 -> 1200 | L42: =(F42+J42)-I42 -> 2200
A43: =المخزون!A42 -> 0 | B43: =المخزون!D42 -> 0 | C43: =المخزون!F32 -> 2026 | D43: 1000 | E43: =المخزون!E42 -> 0 | F43: =D43+E43 -> 1000 | G43: =المخزون!I42 -> 0 | H43: 0.9 | I43: =G43*H43 -> 0 | J43: 1200 | K43: =I43+J43 -> 1200 | L43: =(F43+J43)-I43 -> 2200
A44: =المخزون!A43 -> 0 | B44: =المخزون!D43 -> 0 | C44: =المخزون!F33 -> 2026 | D44: 1000 | E44: =المخزون!E43 -> 0 | F44: =D44+E44 -> 1000 | G44: =المخزون!I43 -> 0 | H44: 0.9 | I44: =G44*H44 -> 0 | J44: 1200 | K44: =I44+J44 -> 1200 | L44: =(F44+J44)-I44 -> 2200
A45: =المخزون!A44 -> 0 | B45: =المخزون!D44 -> 0 | C45: =المخزون!F34 -> 2023 | D45: 1000 | E45: =المخزون!E44 -> 0 | F45: =D45+E45 -> 1000 | G45: =المخزون!I44 -> 0 | H45: 0.9 | I45: =G45*H45 -> 0 | J45: 1200 | K45: =I45+J45 -> 1200 | L45: =(F45+J45)-I45 -> 2200
A46: =المخزون!A45 -> 0 | B46: =المخزون!D45 -> 0 | C46: =المخزون!F35 -> 2022 | D46: 1000 | E46: =المخزون!E45 -> 0 | F46: =D46+E46 -> 1000 | G46: =المخزون!I45 -> 0 | H46: 0.9 | I46: =G46*H46 -> 0 | J46: 1200 | K46: =I46+J46 -> 1200 | L46: =(F46+J46)-I46 -> 2200
A47: =المخزون!A46 -> 0 | B47: =المخزون!D46 -> 0 | C47: =المخزون!F36 -> 2025 | D47: 1000 | E47: =المخزون!E46 -> 0 | F47: =D47+E47 -> 1000 | G47: =المخزون!I46 -> 0 | H47: 0.9 | I47: =G47*H47 -> 0 | J47: 1200 | K47: =I47+J47 -> 1200 | L47: =(F47+J47)-I47 -> 2200
A48: =المخزون!A47 -> 0 | B48: =المخزون!D47 -> 0 | C48: =المخزون!F37 -> 2025 | D48: 1000 | E48: =المخزون!E47 -> 0 | F48: =D48+E48 -> 1000 | G48: =المخزون!I47 -> 0 | H48: 0.9 | I48: =G48*H48 -> 0 | J48: 1200 | K48: =I48+J48 -> 1200 | L48: =(F48+J48)-I48 -> 2200
A49: =المخزون!A48 -> 0 | B49: =المخزون!D48 -> 0 | C49: =المخزون!F38 -> 0 | D49: 1000 | E49: =المخزون!E48 -> 0 | F49: =D49+E49 -> 1000 | G49: =المخزون!I48 -> 0 | H49: 0.9 | I49: =G49*H49 -> 0 | J49: 1200 | K49: =I49+J49 -> 1200 | L49: =(F49+J49)-I49 -> 2200
A50: =المخزون!A49 -> 0 | B50: =المخزون!D49 -> 0 | C50: =المخزون!F39 -> 0 | D50: 1000 | E50: =المخزون!E49 -> 0 | F50: =D50+E50 -> 1000 | G50: =المخزون!I49 -> 0 | H50: 0.9 | I50: =G50*H50 -> 0 | J50: 1200 | K50: =I50+J50 -> 1200 | L50: =(F50+J50)-I50 -> 2200
A51: =المخزون!A50 -> 0 | B51: =المخزون!D50 -> 0 | C51: =المخزون!F40 -> 0 | D51: 1000 | E51: =المخزون!E50 -> 0 | F51: =D51+E51 -> 1000 | G51: =المخزون!I50 -> 0 | H51: 0.9 | I51: =G51*H51 -> 0 | J51: 1200 | K51: =I51+J51 -> 1200 | L51: =(F51+J51)-I51 -> 2200
A52: =المخزون!A51 -> 0 | B52: =المخزون!D51 -> 0 | C52: =المخزون!F41 -> 0 | D52: 1000 | E52: =المخزون!E51 -> 0 | F52: =D52+E52 -> 1000 | G52: =المخزون!I51 -> 0 | H52: 0.9 | I52: =G52*H52 -> 0 | J52: 1200 | K52: =I52+J52 -> 1200 | L52: =(F52+J52)-I52 -> 2200
... A54: =المخزون!A53 -> 0 | B54: =المخزون!D53 -> 0 | C54: =المخزون!F43 -> 0 | D54: 1000 | E54: =المخزون!E53 -> 0 | F54: =D54+E54 -> 1000 | G54: =المخزون!I53 -> 0 | H54: 0.9 | I54: =G54*H54 -> 0 | J54: 1200 | K54: =I54+J54 -> 1200 | L54: =(F54+J54)-I54 -> 2200
A55: =المخزون!A44 -> 0 | B55: =المخزون!D54 -> 0 | C55: =المخزون!F44 -> 0 | D55: 1000 | E55: =المخزون!E54 -> 0 | F55: =D55+E55 -> 1000 | G55: =المخزون!I54 -> 0 | H55: 0.9 | I55: =G55*H55 -> 0 | J55: 1200 | K55: =I55+J55 -> 1200 | L55: =(F55+J55)-I55 -> 2200
A56: =المخزون!A45 -> 0 | B56: =المخزون!D55 -> 0 | C56: =المخزون!F43 -> 0 | D56: 1000 | E56: =المخزون!E45 -> 0 | F56: =D56+E56 -> 1000 | G56: =المخزون!I55 -> 0 | H56: 0.9 | I56: =G56*H56 -> 0 | J56: 1200 | K56: =I56+J56 -> 1200 | L56: =(F56+J56)-I56 -> 2200
A57: =المخزون!A46 -> 0 | B57: =المخزون!D56 -> 0 | C57: =المخزون!F44 -> 0 | D57: 1000 | E57: =المخزون!E46 -> 0 | F57: =D57+E57 -> 1000 | G57: =المخزون!I56 -> 0 | H57: 0.9 | I57: =G57*H57 -> 0 | J57: 1200 | K57: =I57+J57 -> 1200 | L57: =(F57+J57)-I57 -> 2200
A58: =المخزون!A47 -> 0 | B58: =المخزون!D57 -> 0 | C58: =المخزون!F39 -> 0 | D58: 1000 | E58: =المخزون!E45 -> 0 | F58: =D58+E58 -> 1000 | H58: 0.9 | I58: =G58*H58 -> 0 | J58: 1200 | K58: =I58+J58 -> 1200 | L58: =(F58+J58)-I58 -> 2200
A59: =المخزون!A48 -> 0 | B59: =المخزون!D58 -> 0 | C59: =المخزون!F40 -> 0 | D59: 1000 | E59: =المخزون!E46 -> 0 | F59: =D59+E59 -> 1000 | H59: 0.9 | I59: =G59*H59 -> 0 | J59: 1200 | K59: =I59+J59 -> 1200 | L59: =(F59+J59)-I59 -> 2200
A60: =المخزون!A41 -> 0 | B60: =المخزون!D41 -> 0 | C60: =المخزون!F41 -> 0 | D60: 1000 | E60: =المخزون!E41 -> 0 | F60: =D60+E60 -> 1000 | H60: 0.85 | I60: =G60*H60 -> 0 | J60: 1200 | K60: =I60+J60 -> 1200 | L60: =(F60+J60)-I60 -> 2200
...

Sheet تمكين
A1: تمكين | L1: الاوراق المطلوبة والاعتمادات
A2: TYPE/Name | B2: Model | C2: Target Margin | D2: Cost | E2: Price | F2: التخمين | G2: Rate | H2: المبلغ الممول | I2: المصاريف | J2: Total | K2: الدفعة المطلوبة | L2: أي سيارة / تاجير تمويلي (ايجار ينتهي بالتملك)
A4: =المخزون!A3 -> BYD Dolphyn | B4: =المخزون!F3 -> 2022 | C4: 1000 | D4: =المخزون!E3 -> 12800 | E4: =C4+D4 -> 13800 | F4: =المخزون!J3 -> 13500 | G4: 0.85 | H4: =F4*G4 -> 11475 | I4: 850 | J4: =H4+I4 -> 12325 | K4: =(E4+I4)-H4 -> 3175 | L4: هوية
A5: =المخزون!A4 -> Hyundai Enciano | B5: =المخزون!F4 -> 2019 | C5: 1000 | D5: =المخزون!E4 -> 15500 | E5: =C5+D5 -> 16500 | F5: =المخزون!J4 -> Cash Only | G5: 0.85 | H5: =F5*G5 -> #VALUE! | I5: 850 | J5: =H5+I5 -> #VALUE! | K5: =(E5+I5)-H5 -> #VALUE! | L5: كشف ضمان
A6: =المخزون!A5 -> Neta V | B6: =المخزون!F5 -> 2022 | C6: 1000 | D6: =المخزون!E5 -> 9700 | E6: =C6+D6 -> 10700 | F6: =المخزون!J5 -> 0 | G6: 0.85 | H6: =F6*G6 -> 0 | I6: 850 | J6: =H6+I6 -> 850 | K6: =(E6+I6)-H6 -> 11550 | L6: شهادة راتب
A7: =المخزون!A6 -> Neta V | B7: =المخزون!F6 -> 2021 | C7: 1000 | D7: =المخزون!E6 -> 8700 | E7: =C7+D7 -> 9700 | F7: =المخزون!J6 -> 0 | G7: 0.85 | H7: =F7*G7 -> 0 | I7: 850 | J7: =H7+I7 -> 850 | K7: =(E7+I7)-H7 -> 10550 | L7: اي كفيل
A8: =المخزون!A7 -> Neta U / FULL | B8: =المخزون!F7 -> 2022 | C8: 1000 | D8: =المخزون!E7 -> 15000 | E8: =C8+D8 -> 16000 | F8: =المخزون!J7 -> 0 | G8: 0.85 | H8: =F8*G8 -> 0 | I8: 850 | J8: =H8+I8 -> 850 | K8: =(E8+I8)-H8 -> 16850
A9: =المخزون!A8 -> Neta Aya | B9: =المخزون!F8 -> 2023 | C9: 1000 | D9: =المخزون!E8 -> 10100 | E9: =C9+D9 -> 11100 | F9: =المخزون!J8 -> 0 | G9: 0.85 | H9: =F9*G9 -> 0 | I9: 850 | J9: =H9+I9 -> 850 | K9: =(E9+I9)-H9 -> 11950
A10: =المخزون!A9 -> Neta X | B10: =المخزون!F9 -> 2023 | C10: 1000 | D10: =المخزون!E9 -> 15500 | E10: =C10+D10 -> 16500 | F10: =المخزون!J9 -> 0 | G10: 0.85 | H10: =F10*G10 -> 0 | I10: 850 | J10: =H10+I10 -> 850 | K10: =(E10+I10)-H10 -> 17350 | L10: في حالة السجل التجاري يجب ان يكون السجل لسنة او اكثر ويرفق معه كشف حساب و رخصة مهن
A11: =المخزون!A10 -> BYD Yuan Plus | B11: =المخزون!F10 -> 2023 | C11: 1000 | D11: =المخزون!E10 -> 17800 | E11: =C11+D11 -> 18800 | F11: =المخزون!J10 -> 19000 | G11: 0.85 | H11: =F11*G11 -> 16150 | I11: 850 | J11: =H11+I11 -> 17000 | K11: =(E11+I11)-H11 -> 3500
A12: =المخزون!A11 -> Nammi Box Dong Feng | B12: =المخزون!F11 -> 2023 | C12: 1000 | D12: =المخزون!E11 -> 12000 | E12: =C12+D12 -> 13000 | F12: =المخزون!J11 -> Cash Only | G12: 0.85 | H12: =F12*G12 -> #VALUE! | I12: 850 | J12: =H12+I12 -> #VALUE! | K12: =(E12+I12)-H12 -> #VALUE!
A13: =المخزون!A12 -> E Golf | B13: =المخزون!F12 -> 2021 | C13: 1000 | D13: =المخزون!E12 -> 12300 | E13: =C13+D13 -> 13300 | F13: =المخزون!J12 -> 13000 | G13: 0.85 | H13: =F13*G13 -> 11050 | I13: 850 | J13: =H13+I13 -> 11900 | K13: =(E13+I13)-H13 -> 3100
A14: =المخزون!A13 -> LaVida | B14: =المخزون!F13 -> 2019 | C14: 1000 | D14: =المخزون!E13 -> 10700 | E14: =C14+D14 -> 11700 | F14: =المخزون!J13 -> 11700 | G14: 0.85 | H14: =F14*G14 -> 9945 | I14: 850 | J14: =H14+I14 -> 10795 | K14: =(E14+I14)-H14 -> 2605
A15: =المخزون!A14 -> LaVida | B15: =المخزون!F14 -> 2021 | C15: 1000 | D15: =المخزون!E14 -> 11500 | E15: =C15+D15 -> 12500 | F15: =المخزون!J14 -> 13000 | G15: 0.85 | H15: =F15*G15 -> 11050 | I15: 850 | J15: =H15+I15 -> 11900 | K15: =(E15+I15)-H15 -> 2300
A16: =المخزون!A15 -> Nano | B16: =المخزون!F15 -> 2022 | C16: 1000 | D16: =المخزون!E15 -> 8250 | E16: =C16+D16 -> 9250 | F16: =المخزون!J15 -> 9000 | G16: 0.85 | H16: =F16*G16 -> 7650 | I16: 850 | J16: =H16+I16 -> 8500 | K16: =(E16+I16)-H16 -> 2450
A17: =المخزون!A16 -> Honda NS1 | B17: =المخزون!F16 -> 2023 | C17: 1000 | D17: =المخزون!E16 -> 16700 | E17: =C17+D17 -> 17700 | F17: =المخزون!J16 -> 17500 | G17: 0.85 | H17: =F17*G17 -> 14875 | I17: 850 | J17: =H17+I17 -> 15725 | K17: =(E17+I17)-H17 -> 3675 | L17: تمويل فقط BYD Toyota KIA
A18: =المخزون!A17 -> BYD seagall | B18: =المخزون!F17 -> 2024 | C18: 1000 | D18: =المخزون!E17 -> 13250 | E18: =C18+D18 -> 14250 | F18: =المخزون!J17 -> 14500 | G18: 0.85 | H18: =F18*G18 -> 12325 | I18: 850 | J18: =H18+I18 -> 13175 | K18: =(E18+I18)-H18 -> 2775
A19: =المخزون!A18 -> toyota BZ3 | B19: =المخزون!F18 -> 2023 | C19: 1000 | D19: =المخزون!E18 -> 18000 | E19: =C19+D19 -> 19000 | F19: =المخزون!J18 -> 20000 | G19: 0.85 | H19: =F19*G19 -> 17000 | I19: 850 | J19: =H19+I19 -> 17850 | K19: =(E19+I19)-H19 -> 2850
A20: =المخزون!A19 -> KIA EV5 | B20: =المخزون!F19 -> 2023 | C20: 1000 | D20: =المخزون!E19 -> 22000 | E20: =C20+D20 -> 23000 | F20: =المخزون!J19 -> 24000 | G20: 0.85 | H20: =F20*G20 -> 20400 | I20: 850 | J20: =H20+I20 -> 21250 | K20: =(E20+I20)-H20 -> 3450
A21: =المخزون!A20 -> QUIN BYD EV | B21: =المخزون!F20 -> 2023 | C21: 1000 | D21: =المخزون!E20 -> 13000 | E21: =C21+D21 -> 14000 | F21: =المخزون!J20 -> 14500 | G21: 0.85 | H21: =F21*G21 -> 12325 | I21: 850 | J21: =H21+I21 -> 13175 | K21: =(E21+I21)-H21 -> 2525
A22: =المخزون!A21 -> BYD E2 20 305 | B22: =المخزون!F21 -> 2020 | C22: 1000 | D22: =المخزون!E21 -> 11300 | E22: =C22+D22 -> 12300 | F22: =المخزون!J21 -> 12000 | G22: 0.85 | H22: =F22*G22 -> 10200 | I22: 850 | J22: =H22+I22 -> 11050 | K22: =(E22+I22)-H22 -> 2950
A23: =المخزون!A22 -> BYD QIN + EV | B23: =المخزون!F22 -> 2020 | C23: 1000 | D23: =المخزون!E22 -> 10350 | E23: =C23+D23 -> 11350 | F23: =المخزون!J22 -> 12500 | G23: 0.85 | H23: =F23*G23 -> 10625 | I23: 850 | J23: =H23+I23 -> 11475 | K23: =(E23+I23)-H23 -> 1575
A24: =المخزون!A23 -> HONGQUI EMQ5 | B24: =المخزون!F23 -> 2022 | C24: 1000 | D24: =المخزون!E23 -> 14250 | E24: =C24+D24 -> 15250 | F24: =المخزون!J23 -> 16000 | G24: 0.85 | H24: =F24*G24 -> 13600 | I24: 850 | J24: =H24+I24 -> 14450 | K24: =(E24+I24)-H24 -> 2500
A25: =المخزون!A24 -> LEAP T03 | B25: =المخزون!F24 -> 2024 | C25: 1000 | D25: =المخزون!E24 -> 9500 | E25: =C25+D25 -> 10500 | F25: =المخزون!J24 -> 11000 | G25: 0.85 | H25: =F25*G25 -> 9350 | I25: 850 | J25: =H25+I25 -> 10200 | K25: =(E25+I25)-H25 -> 2000
A26: =المخزون!A25 -> FORTHING S60 | B26: =المخزون!F25 -> 2023 | C26: 1000 | D26: =المخزون!E25 -> 13200 | E26: =C26+D26 -> 14200 | F26: =المخزون!J25 -> 14500 | G26: 0.85 | H26: =F26*G26 -> 12325 | I26: 850 | J26: =H26+I26 -> 13175 | K26: =(E26+I26)-H26 -> 2725
A27: =المخزون!A26 -> NANO | B27: =المخزون!F26 -> 2022 | C27: 1000 | D27: =المخزون!E26 -> 8700 | E27: =C27+D27 -> 9700 | F27: =المخزون!J26 -> 0 | G27: 0.85 | H27: =F27*G27 -> 0 | I27: 850 | J27: =H27+I27 -> 850 | K27: =(E27+I27)-H27 -> 10550
A28: =المخزون!A27 -> LEAP T03 | B28: =المخزون!F27 -> 2022 | C28: 1000 | D28: =المخزون!E27 -> 7700 | E28: =C28+D28 -> 8700 | F28: =المخزون!J27 -> 0 | G28: 0.85 | H28: =F28*G28 -> 0 | I28: 850 | J28: =H28+I28 -> 850 | K28: =(E28+I28)-H28 -> 9550
A29: =المخزون!A28 -> Nissan Sylphi | B29: =المخزون!F28 -> 2019 | C29: 1000 | D29: =المخزون!E28 -> 8700 | E29: =C29+D29 -> 9700 | F29: =المخزون!J28 -> 12000 | G29: 0.85 | H29: =F29*G29 -> 10200 | I29: 850 | J29: =H29+I29 -> 11050 | K29: =(E29+I29)-H29 -> 350
... A52: =المخزون!A51 -> 0 | B52: =المخزون!F51 -> 0 | C52: 1000 | D52: =المخزون!E51 -> 0 | E52: =C52+D52 -> 1000 | F52: =المخزون!J51 -> 0 | G52: 0.85 | H52: =F52*G52 -> 0 | I52: 850 | J52: =H52+I52 -> 850 | K52: =(E52+I52)-H52 -> 1850
A53: =المخزون!A52 -> 0 | B53: =المخزون!F52 -> 0 | C53: 1000 | D53: =المخزون!E42 -> 0 | E53: =C53+D53 -> 1000 | F53: =المخزون!J52 -> 0 | G53: 0.85 | H53: =F53*G53 -> 0 | I53: 850 | J53: =H53+I53 -> 850 | K53: =(E53+I53)-H53 -> 1850
A54: =المخزون!A53 -> 0 | B54: =المخزون!F53 -> 0 | C54: 1000 | D54: =المخزون!E43 -> 0 | E54: =C54+D54 -> 1000 | F54: =المخزون!J53 -> 0 | G54: 0.85 | H54: =F54*G54 -> 0 | I54: 850 | J54: =H54+I54 -> 850 | K54: =(E54+I54)-H54 -> 1850
A55: =المخزون!A54 -> 0 | B55: =المخزون!F54 -> 0 | C55: 1000 | D55: =المخزون!E44 -> 0 | E55: =C55+D55 -> 1000 | F55: =المخزون!J54 -> 0 | G55: 0.85 | H55: =F55*G55 -> 0 | I55: 850 | J55: =H55+I55 -> 850 | K55: =(E55+I55)-H55 -> 1850
A56: =المخزون!A55 -> 0 | B56: =المخزون!F55 -> 0 | C56: 1000 | D56: =المخزون!E43 -> 0 | E56: =C56+D56 -> 1000 | F56: =المخزون!J55 -> 0 | G56: 0.85 | H56: =F56*G56 -> 0 | I56: 850 | J56: =H56+I56 -> 850 | K56: =(E56+I56)-H56 -> 1850
A57: =المخزون!A56 -> 0 | B57: =المخزون!F56 -> 0 | C57: 1000 | D57: =المخزون!E44 -> 0 | E57: =C57+D57 -> 1000 | F57: =المخزون!J56 -> 0 | G57: 0.85 | H57: =F57*G57 -> 0 | I57: 850 | J57: =H57+I57 -> 850 | K57: =(E57+I57)-H57 -> 1850
A58: =المخزون!A47 -> 0 | B58: =المخزون!F47 -> 0 | C58: 1000 | D58: =المخزون!E39 -> 0 | E58: =C58+D58 -> 1000 | G58: 0.85 | H58: =F58*G58 -> 0 | I58: 850 | J58: =H58+I58 -> 850 | K58: =(E58+I58)-H58 -> 1850
A59: =المخزون!A48 -> 0 | B59: =المخزون!F48 -> 0 | C59: 1000 | D59: =المخزون!E40 -> 0 | E59: =C59+D59 -> 1000 | G59: 0.85 | H59: =F59*G59 -> 0 | I59: 850 | J59: =H59+I59 -> 850 | K59: =(E59+I59)-H59 -> 1850
A60: =المخزون!A41 -> 0 | B60: =المخزون!F41 -> 0 | C60: 1000 | D60: =المخزون!E41 -> 0 | E60: =C60+D60 -> 1000 | G60: 0.85 | H60: =F60*G60 -> 0 | I60: 850 | J60: =H60+I60 -> 850 | K60: =(E60+I60)-H60 -> 1850
A61: =المخزون!A42 -> 0 | B61: =المخزون!F42 -> 0 | C61: 1000 | D61: =المخزون!E42 -> 0 | E61: =C61+D61 -> 1000 | G61: 0.85 | H61: =F61*G61 -> 0 | I61: 850 | J61: =H61+I61 -> 850 | K61: =(E61+I61)-H61 -> 1850
A62: =المخزون!A43 -> 0 | B62: =المخزون!F43 -> 0 | C62: 1000 | D62: =المخزون!E43 -> 0 | E62: =C62+D62 -> 1000 | G62: 0.85 | H62: =F62*G62 -> 0 | I62: 850 | J62: =H62+I62 -> 850 | K62: =(E62+I62)-H62 -> 1850
A63: =المخزون!A44 -> 0 | B63: =المخزون!F44 -> 0 | C63: 1000 | D63: =المخزون!E44 -> 0 | E63: =C63+D63 -> 1000 | G63: 0.85 | H63: =F63*G63 -> 0 | I63: 850 | J63: =H63+I63 -> 850 | K63: =(E63+I63)-H63 -> 1850

Sheet السماحة
A1: السماحة | L1: الاوراق المطلوبة والاعتمادات
A2: TYPE/Name | B2: Model | C2: Target Margin | D2: Cost | E2: Price | F2: التخمين | G2: Rate | H2: المبلغ الممول | I2: المصاريف | J2: Total | K2: الدفعة المطلوبة | L2: أي سيارة / تنازل ورهن
A4: =المخزون!A3 -> BYD Dolphyn | B4: =المخزون!F3 -> 2022 | C4: 1000 | D4: =المخزون!E3 -> 12800 | E4: =C4+D4 -> 13800 | F4: =المخزون!K3 -> 14800 | G4: 0.85 | H4: =F4*G4 -> 12580 | I4: 700 | J4: =H4+I4 -> 13280 | K4: =(E4+I4)-H4 -> 1920 | L4: هوية
A5: =المخزون!A4 -> Hyundai Enciano | B5: =المخزون!F4 -> 2019 | C5: 1000 | D5: =المخزون!E4 -> 15500 | E5: =C5+D5 -> 16500 | F5: =المخزون!K4 -> Cash Only | G5: 0.85 | H5: =F5*G5 -> #VALUE! | I5: 700 | J5: =H5+I5 -> #VALUE! | K5: =(E5+I5)-H5 -> #VALUE! | L5: كشف ضمان
A6: =المخزون!A5 -> Neta V | B6: =المخزون!F5 -> 2022 | C6: 1000 | D6: =المخزون!E5 -> 9700 | E6: =C6+D6 -> 10700 | F6: =المخزون!K5 -> 12000 | G6: 0.85 | H6: =F6*G6 -> 10200 | I6: 700 | J6: =H6+I6 -> 10900 | K6: =(E6+I6)-H6 -> 1200 | L6: شهادة راتب
A7: =المخزون!A6 -> Neta V | B7: =المخزون!F6 -> 2021 | C7: 1000 | D7: =المخزون!E6 -> 8700 | E7: =C7+D7 -> 9700 | F7: =المخزون!K6 -> 10000 | G7: 0.85 | H7: =F7*G7 -> 8500 | I7: 700 | J7: =H7+I7 -> 9200 | K7: =(E7+I7)-H7 -> 1900 | L7: كفيل درجة اولى
A8: =المخزون!A7 -> Neta U / FULL | B8: =المخزون!F7 -> 2022 | C8: 1000 | D8: =المخزون!E7 -> 15000 | E8: =C8+D8 -> 16000 | F8: =المخزون!K7 -> 17000 | G8: 0.85 | H8: =F8*G8 -> 14450 | I8: 700 | J8: =H8+I8 -> 15150 | K8: =(E8+I8)-H8 -> 2250 | L8: اثبات دخل كفيل درجة اولى
A9: =المخزون!A8 -> Neta Aya | B9: =المخزون!F8 -> 2023 | C9: 1000 | D9: =المخزون!E8 -> 10100 | E9: =C9+D9 -> 11100 | F9: =المخزون!K8 -> 12200 | G9: 0.85 | H9: =F9*G9 -> 10370 | I9: 700 | J9: =H9+I9 -> 11070 | K9: =(E9+I9)-H9 -> 1430
A10: =المخزون!A9 -> Neta X | B10: =المخزون!F9 -> 2023 | C10: 1000 | D10: =المخزون!E9 -> 15500 | E10: =C10+D10 -> 16500 | F10: =المخزون!K9 -> 18000 | G10: 0.85 | H10: =F10*G10 -> 15300 | I10: 700 | J10: =H10+I10 -> 16000 | K10: =(E10+I10)-H10 -> 1900 | L10: في حال كا ن العمل على تطبيقات التوصيل يطلب كفيل درجة اولى بالاضافة الى كفيل عادي
A11: =المخزون!A10 -> BYD Yuan Plus | B11: =المخزون!F10 -> 2023 | C11: 1000 | D11: =المخزون!E10 -> 17800 | E11: =C11+D11 -> 18800 | F11: =المخزون!K10 -> 20000 | G11: 0.85 | H11: =F11*G11 -> 17000 | I11: 700 | J11: =H11+I11 -> 17700 | K11: =(E11+I11)-H11 -> 2500
A12: =المخزون!A11 -> Nammi Box Dong Feng | B12: =المخزون!F11 -> 2023 | C12: 1000 | D12: =المخزون!E11 -> 12000 | E12: =C12+D12 -> 13000 | F12: =المخزون!K11 -> Cash Only | G12: 0.85 | H12: =F12*G12 -> #VALUE! | I12: 700 | J12: =H12+I12 -> #VALUE! | K12: =(E12+I12)-H12 -> #VALUE!
A13: =المخزون!A12 -> E Golf | B13: =المخزون!F12 -> 2021 | C13: 1000 | D13: =المخزون!E12 -> 12300 | E13: =C13+D13 -> 13300 | F13: =المخزون!K12 -> 13500 | G13: 0.85 | H13: =F13*G13 -> 11475 | I13: 700 | J13: =H13+I13 -> 12175 | K13: =(E13+I13)-H13 -> 2525
A14: =المخزون!A13 -> LaVida | B14: =المخزون!F13 -> 2019 | C14: 1000 | D14: =المخزون!E13 -> 10700 | E14: =C14+D14 -> 11700 | F14: =المخزون!K13 -> 12000 | G14: 0.85 | H14: =F14*G14 -> 10200 | I14: 700 | J14: =H14+I14 -> 10900 | K14: =(E14+I14)-H14 -> 2200
A15: =المخزون!A14 -> LaVida | B15: =المخزون!F14 -> 2021 | C15: 1000 | D15: =المخزون!E14 -> 11500 | E15: =C15+D15 -> 12500 | F15: =المخزون!K14 -> 14000 | G15: 0.85 | H15: =F15*G15 -> 11900 | I15: 700 | J15: =H15+I15 -> 12600 | K15: =(E15+I15)-H15 -> 1300
A16: =المخزون!A15 -> Nano | B16: =المخزون!F15 -> 2022 | C16: 1000 | D16: =المخزون!E15 -> 8250 | E16: =C16+D16 -> 9250 | F16: =المخزون!K15 -> 11000 | G16: 0.85 | H16: =F16*G16 -> 9350 | I16: 700 | J16: =H16+I16 -> 10050 | K16: =(E16+I16)-H16 -> 600
A17: =المخزون!A16 -> Honda NS1 | B17: =المخزون!F16 -> 2023 | C17: 1000 | D17: =المخزون!E16 -> 16700 | E17: =C17+D17 -> 17700 | F17: =المخزون!K16 -> 19000 | G17: 0.85 | H17: =F17*G17 -> 16150 | I17: 700 | J17: =H17+I17 -> 16850 | K17: =(E17+I17)-H17 -> 2250
A18: =المخزون!A17 -> BYD seagall | B18: =المخزون!F17 -> 2024 | C18: 1000 | D18: =المخزون!E17 -> 13250 | E18: =C18+D18 -> 14250 | F18: =المخزون!K17 -> 15000 | G18: 0.85 | H18: =F18*G18 -> 12750 | I18: 700 | J18: =H18+I18 -> 13450 | K18: =(E18+I18)-H18 -> 2200
A19: =المخزون!A18 -> toyota BZ3 | B19: =المخزون!F18 -> 2023 | C19: 1000 | D19: =المخزون!E18 -> 18000 | E19: =C19+D19 -> 19000 | F19: =المخزون!K18 -> 20500 | G19: 0.85 | H19: =F19*G19 -> 17425 | I19: 700 | J19: =H19+I19 -> 18125 | K19: =(E19+I19)-H19 -> 2275
A20: =المخزون!A19 -> KIA EV5 | B20: =المخزون!F19 -> 2023 | C20: 1000 | D20: =المخزون!E19 -> 22000 | E20: =C20+D20 -> 23000 | F20: =المخزون!K19 -> 25000 | G20: 0.85 | H20: =F20*G20 -> 21250 | I20: 700 | J20: =H20+I20 -> 21950 | K20: =(E20+I20)-H20 -> 2450
A21: =المخزون!A20 -> QUIN BYD EV | B21: =المخزون!F20 -> 2023 | C21: 1000 | D21: =المخزون!E20 -> 13000 | E21: =C21+D21 -> 14000 | F21: =المخزون!K20 -> 15000 | G21: 0.85 | H21: =F21*G21 -> 12750 | I21: 700 | J21: =H21+I21 -> 13450 | K21: =(E21+I21)-H21 -> 1950
A22: =المخزون!A21 -> BYD E2 20 305 | B22: =المخزون!F21 -> 2020 | C22: 1000 | D22: =المخزون!E21 -> 11300 | E22: =C22+D22 -> 12300 | F22: =المخزون!K21 -> 13000 | G22: 0.85 | H22: =F22*G22 -> 11050 | I22: 700 | J22: =H22+I22 -> 11750 | K22: =(E22+I22)-H22 -> 1950
